<?xml version="1.0" encoding="utf-8"?>
<robot xmlns:xacro="http://www.ros.org/wiki/xacro" name="hand">

  <xacro:macro name="hand" params="connected_to:='' ns:='' rpy:='0 0 0' xyz:='0 0 0' ">
    <xacro:unless value="${connected_to == ''}">
      <joint name="${ns}_hand_joint" type="fixed">
        <parent link="${connected_to}" />
        <child link="${ns}_hand" />
        <origin xyz="${xyz}" rpy="${rpy}" />
      </joint>
    </xacro:unless>

    <link name="${ns}_hand">
      <visual>
        <geometry>
          <mesh filename="package://panda_description/meshes/visual/hand.dae" />
        </geometry>
      </visual>
      <collision>
        <geometry>
          <mesh filename="package://panda_description/meshes/collision/hand.stl" />
        </geometry>
      </collision>
      <inertial>
        <origin xyz="-2.7600000000e-06 -6.1551000000e-04 2.3929520000e-02"
                rpy="0 0 0" />
        <mass value="1.0" />
        <inertia ixx="3.3935288924e-03"  ixy="-5.9251047030e-07"
                 ixz="1.3418921038e-07"  iyy="6.8219719040e-04"
                 iyz="-6.1555761524e-05" izz="3.0707550778e-03" />
      </inertial>
    </link>

    <link name="${ns}_leftfinger">
      <visual>
        <geometry>
          <mesh filename="package://panda_description/meshes/visual/finger.dae" />
        </geometry>
      </visual>
      <collision>
        <geometry>
          <mesh filename="package://panda_description/meshes/collision/finger.stl" />
        </geometry>
      </collision>
      <inertial>
        <origin xyz="-2.4250000000e-05 1.1958490000e-02 2.3781550000e-02"
                rpy="0 0 0" />
        <mass value="0.73" />
        <inertia ixx="1.9009821976e-04" ixy="-1.2251156196e-07"
                 ixz="2.1231749953e-07" iyy="1.8154811386e-04"
                 iyz="2.2800975511e-05" izz="5.5792802358e-05" />
      </inertial>
    </link>

    <link name="${ns}_rightfinger">
      <visual>
        <origin xyz="0 0 0" rpy="0 0 ${pi}" />
        <geometry>
          <mesh filename="package://panda_description/meshes/visual/finger.dae" />
        </geometry>
      </visual>
      <collision>
        <origin xyz="0 0 0" rpy="0 0 ${pi}" />
        <geometry>
          <mesh filename="package://panda_description/meshes/collision/finger.stl" />
        </geometry>
      </collision>
      <inertial>
        <origin xyz="-2.4250000000e-05 1.1958490000e-02 2.3781550000e-02"
                rpy="0 0 0" />
        <mass value="0.73" />
        <inertia ixx="1.9009821976e-04" ixy="-1.2251156196e-07"
                 ixz="2.1231749953e-07" iyy="1.8154811386e-04"
                 iyz="2.2800975511e-05" izz="5.5792802358e-05" />
      </inertial>
    </link>

    <joint name="${ns}_finger_joint1" type="prismatic">
      <parent link="${ns}_hand" />
      <child link="${ns}_leftfinger" />
      <origin xyz="0 0 0.0584" rpy="0 0 0" />
      <axis xyz="0 1 0" />
      <limit effort="20" lower="0.0" upper="0.04" velocity="0.2" />
    </joint>

    <joint name="${ns}_finger_joint2" type="prismatic">
      <parent link="${ns}_hand" />
      <child link="${ns}_rightfinger" />
      <origin xyz="0 0 0.0584" rpy="0 0 0" />
      <axis xyz="0 -1 0" />
      <limit effort="20" lower="0.0" upper="0.04" velocity="0.2" />
      <mimic joint="${ns}_finger_joint1" />
    </joint>
  </xacro:macro>
</robot>
