<?xml version='1.0' encoding='utf-8'?>
<robot xmlns:xacro="http://www.ros.org/wiki/xacro" name="panda">

  <xacro:macro name="panda_arm" params="arm_id:='panda' description_pkg:='panda_description' connected_to:='' xyz:='0 0 0' rpy:='0 0 0'">
    <xacro:unless value="${not connected_to}">
      <joint name="${arm_id}_joint_${connected_to}" type="fixed">
        <parent link="${connected_to}" />
        <child link="${arm_id}_link0" />
        <origin rpy="${rpy}" xyz="${xyz}" />
      </joint>
    </xacro:unless>

    <link name="${arm_id}_link0">
      <visual>
        <geometry>
          <mesh filename="package://${description_pkg}/meshes/visual/link0.dae" />
        </geometry>
      </visual>
      <collision>
        <geometry>
          <mesh filename="package://${description_pkg}/meshes/collision/link0.stl" />
        </geometry>
      </collision>
      <inertial>
        <origin xyz="-2.9189750000e-02 -8.7947000000e-04 5.6603190000e-02"
                rpy="0 0 0" />
        <mass value="1.0" />
        <inertia ixx="3.0208907507e-03"  ixy="-1.9469434530e-05"
                 ixz="-4.5987519329e-04" iyy="3.9017274973e-03"
                 iyz="-4.1208729424e-07" izz="4.0286070431e-03" />
      </inertial>
    </link>

    <link name="${arm_id}_link1">
      <visual>
        <geometry>
          <mesh filename="package://${description_pkg}/meshes/visual/link1.dae" />
        </geometry>
      </visual>
      <collision>
        <geometry>
          <mesh filename="package://${description_pkg}/meshes/collision/link1.stl" />
        </geometry>
      </collision>
      <inertial>
        <origin xyz="1.1400000000e-05 -3.1265540000e-02 -6.9373290000e-02"
                rpy="0 0 0" />
        <mass value="1.0" />
        <inertia ixx="5.9226730485e-03" ixy="1.4245315766e-07"
                 ixz="3.8568507530e-07" iyy="5.1298138460e-03"
                 iyz="1.1560796647e-03" izz="2.3931512155e-03" />
      </inertial>
    </link>

    <joint name="${arm_id}_joint1" type="revolute">
      <safety_controller k_position="100.0" k_velocity="40.0" soft_lower_limit="-2.8973" soft_upper_limit="2.8973" />
      <origin rpy="0 0 0" xyz="0 0 0.333" />
      <parent link="${arm_id}_link0" />
      <child link="${arm_id}_link1" />
      <axis xyz="0 0 1" />
      <limit effort="87" lower="-2.9671" upper="2.9671" velocity="2.3925" />
    </joint>

    <link name="${arm_id}_link2">
      <visual>
        <geometry>
          <mesh filename="package://${description_pkg}/meshes/visual/link2.dae" />
        </geometry>
      </visual>
      <collision>
        <geometry>
          <mesh filename="package://${description_pkg}/meshes/collision/link2.stl" />
        </geometry>
      </collision>
      <inertial>
        <origin xyz="-1.3180000000e-05 -7.0321540000e-02 3.1178270000e-02"
                rpy="0 0 0" />
        <mass value="1.0" />
        <inertia ixx="5.9962199438e-03"  ixy="-6.7615014029e-07"
                 ixz="-2.3493516929e-07" iyy="2.3948403893e-03"
                 iyz="-1.1636087632e-03" izz="5.2033249732e-03" />
      </inertial>
    </link>

    <joint name="${arm_id}_joint2" type="revolute">
      <safety_controller k_position="100.0" k_velocity="40.0" soft_lower_limit="-1.7628" soft_upper_limit="1.7628" />
      <origin rpy="${-pi/2} 0 0" xyz="0 0 0" />
      <parent link="${arm_id}_link1" />
      <child link="${arm_id}_link2" />
      <axis xyz="0 0 1" />
      <limit effort="87" lower="-1.8326" upper="1.8326" velocity="2.3925" />
    </joint>

    <link name="${arm_id}_link3">
      <visual>
        <geometry>
          <mesh filename="package://${description_pkg}/meshes/visual/link3.dae"/>
        </geometry>
      </visual>
      <collision>
        <geometry>
          <mesh filename="package://${description_pkg}/meshes/collision/link3.stl" />
        </geometry>
      </collision>
      <inertial>
        <origin xyz="4.4348280000e-02 2.4928320000e-02 -3.8130030000e-02"
                rpy="0 0 0" />
        <mass value="0.78" />
        <inertia ixx="2.4814391703e-03"  ixy="-4.8315843437e-04"
                 ixz="-8.2557114619e-04" iyy="2.9935310139e-03"
                 iyz="-4.4604815446e-04" izz="2.5083810118e-03" />
      </inertial>
    </link>

    <joint name="${arm_id}_joint3" type="revolute">
      <safety_controller k_position="100.0" k_velocity="40.0" soft_lower_limit="-2.8973" soft_upper_limit="2.8973" />
      <origin rpy="${pi/2} 0 0" xyz="0 -0.316 0" />
      <parent link="${arm_id}_link2" />
      <child link="${arm_id}_link3" />
      <axis xyz="0 0 1" />
      <limit effort="87" lower="-2.9671" upper="2.9671" velocity="2.3925" />
    </joint>

    <link name="${arm_id}_link4">
      <visual>
        <geometry>
          <mesh filename="package://${description_pkg}/meshes/visual/link4.dae" />
        </geometry>
      </visual>
      <collision>
        <geometry>
          <mesh filename="package://${description_pkg}/meshes/collision/link4.stl" />
        </geometry>
      </collision>
      <inertial>
        <origin xyz="-3.8550270000e-02 3.9525550000e-02 2.4716210000e-02"
                rpy="0 0 0" />
        <mass value="0.79" />
        <inertia ixx="2.5698770428e-03"  ixy="8.5226293644e-04"
                 ixz="-4.8914733021e-04" iyy="2.5435632961e-03"
                 iyz="4.6078342421e-04"  izz="3.0898802746e-03" />
      </inertial>
    </link>

    <joint name="${arm_id}_joint4" type="revolute">
      <safety_controller k_position="100.0" k_velocity="40.0" soft_lower_limit="-3.0718" soft_upper_limit="0.0175" />
      <origin rpy="${pi/2} 0 0" xyz="0.0825 0 0" />
      <parent link="${arm_id}_link3" />
      <child link="${arm_id}_link4" />
      <axis xyz="0 0 1" />
      <limit effort="87" lower="-3.1416" upper="0.0873" velocity="2.3925" />
    </joint>

    <link name="${arm_id}_link5">
      <visual>
        <geometry>
          <mesh filename="package://${description_pkg}/meshes/visual/link5.dae" />
        </geometry>
      </visual>
      <collision>
        <geometry>
          <mesh filename="package://${description_pkg}/meshes/collision/link5.stl" />
        </geometry>
      </collision>
      <inertial>
        <origin xyz="-6.3700000000e-05 3.8412360000e-02 -1.0997013000e-01"
                rpy="0 0 0" />
        <mass value="1.14" />
        <inertia ixx="9.9489526162e-03"  ixy="-3.0923971423e-06"
                 ixz="-1.3276013105e-05" iyy="9.0449844181e-03"
                 iyz="-1.9558597152e-03" izz="2.5774715454e-03" />
      </inertial>
    </link>

    <joint name="${arm_id}_joint5" type="revolute">
      <safety_controller k_position="100.0" k_velocity="40.0" soft_lower_limit="-2.8973" soft_upper_limit="2.8973" />
      <origin rpy="${-pi/2} 0 0" xyz="-0.0825 0.384 0" />
      <parent link="${arm_id}_link4" />
      <child link="${arm_id}_link5" />
      <axis xyz="0 0 1" />
      <limit effort="12" lower="-2.9671" upper="2.9671" velocity="2.8710" />
    </joint>

    <link name="${arm_id}_link6">
      <visual>
        <geometry>
          <mesh filename="package://${description_pkg}/meshes/visual/link6.dae" />
        </geometry>
      </visual>
      <collision>
        <geometry>
          <mesh filename="package://${description_pkg}/meshes/collision/link6.stl" />
        </geometry>
      </collision>
      <inertial>
        <origin xyz="5.1002280000e-02 6.9326700000e-03 6.1689700000e-03"
                rpy="0 0 0" />
        <mass value="0.48" />
        <inertia ixx="7.7550750204e-04" ixy="-5.4535229445e-05"
                 ixz="9.8447394353e-05" iyy="1.1843242027e-03"
                 iyz="9.7507874688e-06" izz="1.4430443083e-03" />
      </inertial>
    </link>

    <joint name="${arm_id}_joint6" type="revolute">
      <safety_controller k_position="100.0" k_velocity="40.0" soft_lower_limit="-0.0175" soft_upper_limit="3.7525" />
      <origin rpy="${pi/2} 0 0" xyz="0 0 0" />
      <parent link="${arm_id}_link5" />
      <child link="${arm_id}_link6" />
      <axis xyz="0 0 1" />
      <limit effort="12" lower="-0.0873" upper="3.8223" velocity="2.8710" />
    </joint>

    <link name="${arm_id}_link7">
      <visual>
        <geometry>
          <mesh filename="package://${description_pkg}/meshes/visual/link7.dae" />
        </geometry>
      </visual>
      <collision>
        <geometry>
          <mesh filename="package://${description_pkg}/meshes/collision/link7.stl" />
        </geometry>
      </collision>
      <inertial>
        <origin xyz="1.0361390000e-02 1.0359650000e-02 7.9107730000e-02"
                rpy="0 0 0" />
        <mass value="1.49" />
        <inertia ixx="1.4440550235e-03"  ixy="-4.4171751527e-04"
                 ixz="-4.8331020139e-05" iyy="1.4430197316e-03"
                 iyz="-4.8495088634e-05" izz="2.2729277029e-03" />
      </inertial>
    </link>

    <joint name="${arm_id}_joint7" type="revolute">
      <safety_controller k_position="100.0" k_velocity="40.0" soft_lower_limit="-2.8973" soft_upper_limit="2.8973" />
      <origin rpy="${pi/2} 0 0" xyz="0.088 0 0" />
      <parent link="${arm_id}_link6" />
      <child link="${arm_id}_link7" />
      <axis xyz="0 0 1" />
      <limit effort="12" lower="-2.9671" upper="2.9671" velocity="2.8710" />
    </joint>

    <link name="${arm_id}_link8" />

    <joint name="${arm_id}_joint8" type="fixed">
      <origin rpy="0 0 0" xyz="0 0 0.107" />
      <parent link="${arm_id}_link7" />
      <child link="${arm_id}_link8" />
      <axis xyz="0 0 0" />
    </joint>
  </xacro:macro>
</robot>
